Process SpawnProcess-1:
Traceback (most recent call last):
  File "C:\Users\cwoh\AppData\Local\Programs\Python\Python310\lib\site-packages\pydantic_settings\sources\base.py", line 490, in __call__
    field_value = self.prepare_field_value(field_name, field, field_value, value_is_complex)
  File "C:\Users\cwoh\AppData\Local\Programs\Python\Python310\lib\site-packages\pydantic_settings\sources\providers\env.py", line 120, in prepare_field_value
    raise e
  File "C:\Users\cwoh\AppData\Local\Programs\Python\Python310\lib\site-packages\pydantic_settings\sources\providers\env.py", line 117, in prepare_field_value
    value = self.decode_complex_value(field_name, field, value)
  File "C:\Users\cwoh\AppData\Local\Programs\Python\Python310\lib\site-packages\pydantic_settings\sources\base.py", line 186, in decode_complex_value
    return json.loads(value)
  File "C:\Users\cwoh\AppData\Local\Programs\Python\Python310\lib\json\__init__.py", line 346, in loads
    return _default_decoder.decode(s)
  File "C:\Users\cwoh\AppData\Local\Programs\Python\Python310\lib\json\decoder.py", line 337, in decode
    obj, end = self.raw_decode(s, idx=_w(s, 0).end())
  File "C:\Users\cwoh\AppData\Local\Programs\Python\Python310\lib\json\decoder.py", line 355, in raw_decode
    raise JSONDecodeError("Expecting value", s, err.value) from None
json.decoder.JSONDecodeError: Expecting value: line 1 column 1 (char 0)

The above exception was the direct cause of the following exception:

Traceback (most recent call last):
  File "C:\Users\cwoh\AppData\Local\Programs\Python\Python310\lib\multiprocessing\process.py", line 314, in _bootstrap
    self.run()
  File "C:\Users\cwoh\AppData\Local\Programs\Python\Python310\lib\multiprocessing\process.py", line 108, in run
    self._target(*self._args, **self._kwargs)
  File "C:\Users\cwoh\AppData\Local\Programs\Python\Python310\lib\site-packages\uvicorn\_subprocess.py", line 80, in subprocess_started
    target(sockets=sockets)
  File "C:\Users\cwoh\AppData\Local\Programs\Python\Python310\lib\site-packages\uvicorn\server.py", line 67, in run
    return asyncio.run(self.serve(sockets=sockets))
  File "C:\Users\cwoh\AppData\Local\Programs\Python\Python310\lib\asyncio\runners.py", line 44, in run
    return loop.run_until_complete(main)
  File "C:\Users\cwoh\AppData\Local\Programs\Python\Python310\lib\asyncio\base_events.py", line 649, in run_until_complete
    return future.result()
  File "C:\Users\cwoh\AppData\Local\Programs\Python\Python310\lib\site-packages\uvicorn\server.py", line 71, in serve
    await self._serve(sockets)
  File "C:\Users\cwoh\AppData\Local\Programs\Python\Python310\lib\site-packages\uvicorn\server.py", line 78, in _serve
    config.load()
  File "C:\Users\cwoh\AppData\Local\Programs\Python\Python310\lib\site-packages\uvicorn\config.py", line 436, in load
    self.loaded_app = import_from_string(self.app)
  File "C:\Users\cwoh\AppData\Local\Programs\Python\Python310\lib\site-packages\uvicorn\importer.py", line 19, in import_from_string
    module = importlib.import_module(module_str)
  File "C:\Users\cwoh\AppData\Local\Programs\Python\Python310\lib\importlib\__init__.py", line 126, in import_module
    return _bootstrap._gcd_import(name[level:], package, level)
  File "<frozen importlib._bootstrap>", line 1050, in _gcd_import
  File "<frozen importlib._bootstrap>", line 1027, in _find_and_load
  File "<frozen importlib._bootstrap>", line 1006, in _find_and_load_unlocked
  File "<frozen importlib._bootstrap>", line 688, in _load_unlocked
  File "<frozen importlib._bootstrap_external>", line 883, in exec_module
  File "<frozen importlib._bootstrap>", line 241, in _call_with_frames_removed
  File "C:\Users\cwoh\Desktop\01. Project\03. Platform\3. Test\backend\app\main.py", line 8, in <module>
    from app.config import settings
  File "C:\Users\cwoh\Desktop\01. Project\03. Platform\3. Test\backend\app\config.py", line 52, in <module>
    settings = Settings()
  File "C:\Users\cwoh\AppData\Local\Programs\Python\Python310\lib\site-packages\pydantic_settings\main.py", line 189, in __init__
    **__pydantic_self__._settings_build_values(
  File "C:\Users\cwoh\AppData\Local\Programs\Python\Python310\lib\site-packages\pydantic_settings\main.py", line 424, in _settings_build_values
    source_state = source()
  File "C:\Users\cwoh\AppData\Local\Programs\Python\Python310\lib\site-packages\pydantic_settings\sources\providers\dotenv.py", line 106, in __call__
    data: dict[str, Any] = super().__call__()
  File "C:\Users\cwoh\AppData\Local\Programs\Python\Python310\lib\site-packages\pydantic_settings\sources\base.py", line 492, in __call__
    raise SettingsError(
pydantic_settings.exceptions.SettingsError: error parsing value for field "CORS_ORIGINS" from source "DotEnvSettingsSource"
