[2025-08-25 16:51:07,351] ERROR in app: Exception on /auth/login [GET]
Traceback (most recent call last):
  File "C:\Users\cwoh\AppData\Local\Programs\Python\Python310\lib\site-packages\flask\app.py", line 1511, in wsgi_app
    response = self.full_dispatch_request()
  File "C:\Users\cwoh\AppData\Local\Programs\Python\Python310\lib\site-packages\flask\app.py", line 919, in full_dispatch_request
    rv = self.handle_user_exception(e)
  File "C:\Users\cwoh\AppData\Local\Programs\Python\Python310\lib\site-packages\flask\app.py", line 915, in full_dispatch_request
    rv = self.preprocess_request()
  File "C:\Users\cwoh\AppData\Local\Programs\Python\Python310\lib\site-packages\flask\app.py", line 1291, in preprocess_request
    rv = self.ensure_sync(before_func)()
  File "C:\Users\cwoh\AppData\Local\Programs\Python\Python310\lib\site-packages\dash\dash.py", line 2501, in router
    _validate.check_for_duplicate_pathnames(_pages.PAGE_REGISTRY)
  File "C:\Users\cwoh\AppData\Local\Programs\Python\Python310\lib\site-packages\dash\_validate.py", line 479, in check_for_duplicate_pathnames
    raise Exception(f"modules {modules} have duplicate paths")
Exception: modules ['app.ui.pages.home', 'pages.home'] have duplicate paths
